{"uuid": "4469e425-5832-4f18-b433-e7c1225c2db1", "children": ["b5290469-9ed2-41f5-b29c-4a11d1f188af"], "befores": [{"name": "Подключаем удаленный или локальный драйвер в зависимости от флага REMOTE_DRIVER", "status": "broken", "statusDetails": {"message": "selenium.common.exceptions.SessionNotCreatedException: Message: create container: Error response from daemon: No such image: seleniarm/standalone-chromium:114.0; For documentation on this error, please visit: https://www.selenium.dev/documentation/webdriver/troubleshooting/errors#sessionnotcreatedexception\n\n", "trace": "  File \"/usr/local/lib/python3.9/site-packages/pluggy/_callers.py\", line 38, in run_old_style_hookwrapper\n    res = yield\n  File \"/usr/local/lib/python3.9/site-packages/pluggy/_callers.py\", line 139, in _multicall\n    teardown.throw(exception)\n  File \"/usr/local/lib/python3.9/site-packages/_pytest/setuponly.py\", line 36, in pytest_fixture_setup\n    return (yield)\n  File \"/usr/local/lib/python3.9/site-packages/pluggy/_callers.py\", line 121, in _multicall\n    res = hook_impl.function(*args)\n  File \"/usr/local/lib/python3.9/site-packages/_pytest/fixtures.py\", line 1196, in pytest_fixture_setup\n    result = call_fixture_func(fixturefunc, request, kwargs)\n  File \"/usr/local/lib/python3.9/site-packages/_pytest/fixtures.py\", line 923, in call_fixture_func\n    fixture_result = next(generator)\n  File \"/app/tests/conftest.py\", line 21, in driver\n    driver = webdriver.Remote(\n  File \"/usr/local/lib/python3.9/site-packages/selenium/webdriver/remote/webdriver.py\", line 263, in __init__\n    self.start_session(capabilities)\n  File \"/usr/local/lib/python3.9/site-packages/selenium/webdriver/remote/webdriver.py\", line 366, in start_session\n    response = self.execute(Command.NEW_SESSION, caps)[\"value\"]\n  File \"/usr/local/lib/python3.9/site-packages/selenium/webdriver/remote/webdriver.py\", line 458, in execute\n    self.error_handler.check_response(response)\n  File \"/usr/local/lib/python3.9/site-packages/selenium/webdriver/remote/errorhandler.py\", line 232, in check_response\n    raise exception_class(message, screen, stacktrace)\n"}, "start": 1759503918782, "stop": 1759503918785}], "start": 1759503918782, "stop": 1759503918803}